<mujoco model="ball paddle">
  <default>
    <joint armature="0.01" damping=".1" limited="true"/>
    <geom conaffinity="0" condim="3" contype="1" density="1000" friction="0.8 .1 .1" rgba="0.8 0.6 .4 1"/>
  </default>
  <option integrator="RK4" timestep="0.002"/>

  <worldbody>
    <light cutoff="100" diffuse="1 1 1" dir="-0 0 -1.3" directional="true" exponent="1" pos="0 0 1.3" specular=".1 .1 .1"/>
    <geom conaffinity="1" condim="3" name="floor" pos="0 0 0" rgba="0.8 0.9 0.8 1" size="40 40 40" type="plane" material="MatPlane"/>
    <body name="ball" pos="0 0 10">
      <joint armature="0" axis="1 0 0" damping="0" limited="false" name="ignorex" pos="0 0 0" stiffness="0" type="slide"/>
      <joint armature="0" axis="0 0 1" damping="0" limited="false" name="ignorez" pos="0 0 0" stiffness="0" type="slide"/>
      <joint armature="0" axis="0 1 0" damping="0" limited="false" name="ignorey" pos="0 0 0" stiffness="0" type="slide"/>
      <!-- <light name="light" directional="true" diffuse=".6 .6 .6" pos="0 0 2" specular=".3 .3 .3"/> -->
      <!-- <geom name="ground" type="plane" pos="0 0 0" size=".6 .2 10"/> -->
      <geom name="ball" type="sphere" mass="10.0" size=".5"/>
    </body>
  </worldbody>
  
  <asset>
    <texture type="skybox" builtin="gradient" rgb1=".4 .5 .6" rgb2="0 0 0"
             width="100" height="100"/>
    <texture builtin="flat" height="1278" mark="cross" markrgb="1 1 1" name="texgeom" random="0.01" rgb1="0.8 0.6 0.4" rgb2="0.8 0.6 0.4" type="cube" width="127"/>
    <texture builtin="checker" height="100" name="texplane" rgb1="0 0 0" rgb2="0.8 0.8 0.8" type="2d" width="100"/>
    <material name="MatPlane" reflectance="0.5" shininess="1" specular="1" texrepeat="60 60" texture="texplane"/>
    <material name="geom" texture="texgeom" texuniform="true"/>
  </asset>
  
</mujoco>
